package mhfc.heltrato.common.world;

import java.util.Random;

import net.minecraft.block.Block;
import net.minecraft.block.material.Material;
import net.minecraft.init.Blocks;
import net.minecraft.world.World;
import net.minecraft.world.gen.feature.WorldGenerator;

public class GoatenHouseA extends WorldGenerator
{
	protected Block[] GetValidSpawnBlocks()
	{
		return new Block[]
		{
			Blocks.grass,
		};
	}

	public boolean LocationIsValidSpawn(World world, int x, int y, int z)
	{
		int distanceToAir = 0;
		Block checkBlock = world.getBlock(x, y, z);

		while (checkBlock != Blocks.air)
		{
			distanceToAir++;
			checkBlock = world.getBlock(x, y + distanceToAir, z);
		}

		if (distanceToAir > 1)
		{
			return false;
		}

		y += distanceToAir - 1;

		Block block = world.getBlock(x, y, z);
		Block blockAbove = world.getBlock(x, y + 1, z);
		Block blockBelow = world.getBlock(x, y - 1, z);

		for (Block i : GetValidSpawnBlocks())
		{
			if (blockAbove != Blocks.air)
			{
				return false;
			}
			if (block == i)
			{
				return true;
			}
			else if (block == Blocks.snow_layer && blockBelow == i)
			{
				return true;
			}
			else if (block.getMaterial() == Material.plants && blockBelow == i)
			{
				return true;
			}
		}
		return false;
	}

	public boolean generate(World world, Random rand, int x, int y, int z)
	{
		if(!LocationIsValidSpawn(world, x, y, z) || !LocationIsValidSpawn(world, x + 15, y, z) || !LocationIsValidSpawn(world, x + 15, y, z + 17) || !LocationIsValidSpawn(world, x, y, z + 17))
		{
			return false;
		}

		world.setBlock(x + 0, y + 0, z + 0, Blocks.grass, 0, 3);
		world.setBlock(x + 1, y + 0, z + 0, Blocks.grass, 0, 3);
		world.setBlock(x + 2, y + 0, z + 0, Blocks.grass, 0, 3);
		world.setBlock(x + 3, y + 0, z + 0, Blocks.grass, 0, 3);
		world.setBlock(x + 4, y + 0, z + 0, Blocks.grass, 0, 3);
		world.setBlock(x + 5, y + 0, z + 0, Blocks.grass, 0, 3);
		world.setBlock(x + 6, y + 0, z + 0, Blocks.grass, 0, 3);
		world.setBlock(x + 7, y + 0, z + 0, Blocks.grass, 0, 3);
		world.setBlock(x + 8, y + 0, z + 0, Blocks.grass, 0, 3);
		world.setBlock(x + 9, y + 0, z + 0, Blocks.grass, 0, 3);
		world.setBlock(x + 10, y + 0, z + 0, Blocks.grass, 0, 3);
		world.setBlock(x + 11, y + 0, z + 0, Blocks.grass, 0, 3);
		world.setBlock(x + 12, y + 0, z + 0, Blocks.grass, 0, 3);
		world.setBlock(x + 13, y + 0, z + 0, Blocks.grass, 0, 3);
		world.setBlock(x + 14, y + 0, z + 0, Blocks.grass, 0, 3);
		world.setBlock(x + 15, y + 0, z + 0, Blocks.grass, 0, 3);
		world.setBlock(x + 0, y + 0, z + 1, Blocks.grass, 0, 3);
		world.setBlock(x + 1, y + 0, z + 1, Blocks.dirt, 0, 3);
		world.setBlock(x + 2, y + 0, z + 1, Blocks.dirt, 0, 3);
		world.setBlock(x + 3, y + 0, z + 1, Blocks.dirt, 0, 3);
		world.setBlock(x + 4, y + 0, z + 1, Blocks.dirt, 0, 3);
		world.setBlock(x + 5, y + 0, z + 1, Blocks.dirt, 0, 3);
		world.setBlock(x + 6, y + 0, z + 1, Blocks.dirt, 0, 3);
		world.setBlock(x + 7, y + 0, z + 1, Blocks.dirt, 0, 3);
		world.setBlock(x + 8, y + 0, z + 1, Blocks.dirt, 0, 3);
		world.setBlock(x + 9, y + 0, z + 1, Blocks.dirt, 0, 3);
		world.setBlock(x + 10, y + 0, z + 1, Blocks.dirt, 0, 3);
		world.setBlock(x + 11, y + 0, z + 1, Blocks.dirt, 0, 3);
		world.setBlock(x + 12, y + 0, z + 1, Blocks.dirt, 0, 3);
		world.setBlock(x + 13, y + 0, z + 1, Blocks.dirt, 0, 3);
		world.setBlock(x + 14, y + 0, z + 1, Blocks.dirt, 0, 3);
		world.setBlock(x + 15, y + 0, z + 1, Blocks.dirt, 0, 3);
		world.setBlock(x + 0, y + 0, z + 2, Blocks.grass, 0, 3);
		world.setBlock(x + 1, y + 0, z + 2, Blocks.dirt, 0, 3);
		world.setBlock(x + 2, y + 0, z + 2, Blocks.grass, 0, 3);
		world.setBlock(x + 3, y + 0, z + 2, Blocks.grass, 0, 3);
		world.setBlock(x + 4, y + 0, z + 2, Blocks.grass, 0, 3);
		world.setBlock(x + 5, y + 0, z + 2, Blocks.grass, 0, 3);
		world.setBlock(x + 6, y + 0, z + 2, Blocks.grass, 0, 3);
		world.setBlock(x + 7, y + 0, z + 2, Blocks.grass, 0, 3);
		world.setBlock(x + 8, y + 0, z + 2, Blocks.grass, 0, 3);
		world.setBlock(x + 9, y + 0, z + 2, Blocks.grass, 0, 3);
		world.setBlock(x + 10, y + 0, z + 2, Blocks.grass, 0, 3);
		world.setBlock(x + 11, y + 0, z + 2, Blocks.grass, 0, 3);
		world.setBlock(x + 12, y + 0, z + 2, Blocks.grass, 0, 3);
		world.setBlock(x + 13, y + 0, z + 2, Blocks.grass, 0, 3);
		world.setBlock(x + 14, y + 0, z + 2, Blocks.grass, 0, 3);
		world.setBlock(x + 15, y + 0, z + 2, Blocks.dirt, 0, 3);
		world.setBlock(x + 0, y + 0, z + 3, Blocks.grass, 0, 3);
		world.setBlock(x + 1, y + 0, z + 3, Blocks.dirt, 0, 3);
		world.setBlock(x + 2, y + 0, z + 3, Blocks.grass, 0, 3);
		world.setBlock(x + 3, y + 0, z + 3, Blocks.grass, 0, 3);
		world.setBlock(x + 4, y + 0, z + 3, Blocks.dirt, 0, 3);
		world.setBlock(x + 5, y + 0, z + 3, Blocks.grass, 0, 3);
		world.setBlock(x + 6, y + 0, z + 3, Blocks.grass, 0, 3);
		world.setBlock(x + 7, y + 0, z + 3, Blocks.grass, 0, 3);
		world.setBlock(x + 8, y + 0, z + 3, Blocks.grass, 0, 3);
		world.setBlock(x + 9, y + 0, z + 3, Blocks.grass, 0, 3);
		world.setBlock(x + 10, y + 0, z + 3, Blocks.grass, 0, 3);
		world.setBlock(x + 11, y + 0, z + 3, Blocks.grass, 0, 3);
		world.setBlock(x + 12, y + 0, z + 3, Blocks.grass, 0, 3);
		world.setBlock(x + 13, y + 0, z + 3, Blocks.grass, 0, 3);
		world.setBlock(x + 14, y + 0, z + 3, Blocks.grass, 0, 3);
		world.setBlock(x + 15, y + 0, z + 3, Blocks.dirt, 0, 3);
		world.setBlock(x + 0, y + 0, z + 4, Blocks.grass, 0, 3);
		world.setBlock(x + 1, y + 0, z + 4, Blocks.dirt, 0, 3);
		world.setBlock(x + 2, y + 0, z + 4, Blocks.grass, 0, 3);
		world.setBlock(x + 3, y + 0, z + 4, Blocks.grass, 0, 3);
		world.setBlock(x + 4, y + 0, z + 4, Blocks.grass, 0, 3);
		world.setBlock(x + 5, y + 0, z + 4, Blocks.grass, 0, 3);
		world.setBlock(x + 6, y + 0, z + 4, Blocks.grass, 0, 3);
		world.setBlock(x + 7, y + 0, z + 4, Blocks.grass, 0, 3);
		world.setBlock(x + 8, y + 0, z + 4, Blocks.grass, 0, 3);
		world.setBlock(x + 9, y + 0, z + 4, Blocks.grass, 0, 3);
		world.setBlock(x + 10, y + 0, z + 4, Blocks.grass, 0, 3);
		world.setBlock(x + 11, y + 0, z + 4, Blocks.grass, 0, 3);
		world.setBlock(x + 12, y + 0, z + 4, Blocks.grass, 0, 3);
		world.setBlock(x + 13, y + 0, z + 4, Blocks.grass, 0, 3);
		world.setBlock(x + 14, y + 0, z + 4, Blocks.grass, 0, 3);
		world.setBlock(x + 15, y + 0, z + 4, Blocks.grass, 0, 3);
		world.setBlock(x + 0, y + 0, z + 5, Blocks.grass, 0, 3);
		world.setBlock(x + 1, y + 0, z + 5, Blocks.dirt, 0, 3);
		world.setBlock(x + 2, y + 0, z + 5, Blocks.dirt, 0, 3);
		world.setBlock(x + 3, y + 0, z + 5, Blocks.grass, 0, 3);
		world.setBlock(x + 4, y + 0, z + 5, Blocks.grass, 0, 3);
		world.setBlock(x + 5, y + 0, z + 5, Blocks.grass, 0, 3);
		world.setBlock(x + 6, y + 0, z + 5, Blocks.dirt, 0, 3);
		world.setBlock(x + 7, y + 0, z + 5, Blocks.grass, 0, 3);
		world.setBlock(x + 8, y + 0, z + 5, Blocks.grass, 0, 3);
		world.setBlock(x + 9, y + 0, z + 5, Blocks.grass, 0, 3);
		world.setBlock(x + 10, y + 0, z + 5, Blocks.grass, 0, 3);
		world.setBlock(x + 11, y + 0, z + 5, Blocks.grass, 0, 3);
		world.setBlock(x + 12, y + 0, z + 5, Blocks.grass, 0, 3);
		world.setBlock(x + 13, y + 0, z + 5, Blocks.grass, 0, 3);
		world.setBlock(x + 14, y + 0, z + 5, Blocks.grass, 0, 3);
		world.setBlock(x + 15, y + 0, z + 5, Blocks.dirt, 0, 3);
		world.setBlock(x + 0, y + 0, z + 6, Blocks.grass, 0, 3);
		world.setBlock(x + 1, y + 0, z + 6, Blocks.dirt, 0, 3);
		world.setBlock(x + 2, y + 0, z + 6, Blocks.grass, 0, 3);
		world.setBlock(x + 3, y + 0, z + 6, Blocks.grass, 0, 3);
		world.setBlock(x + 4, y + 0, z + 6, Blocks.grass, 0, 3);
		world.setBlock(x + 5, y + 0, z + 6, Blocks.grass, 0, 3);
		world.setBlock(x + 6, y + 0, z + 6, Blocks.grass, 0, 3);
		world.setBlock(x + 7, y + 0, z + 6, Blocks.grass, 0, 3);
		world.setBlock(x + 8, y + 0, z + 6, Blocks.grass, 0, 3);
		world.setBlock(x + 9, y + 0, z + 6, Blocks.grass, 0, 3);
		world.setBlock(x + 10, y + 0, z + 6, Blocks.grass, 0, 3);
		world.setBlock(x + 11, y + 0, z + 6, Blocks.grass, 0, 3);
		world.setBlock(x + 12, y + 0, z + 6, Blocks.grass, 0, 3);
		world.setBlock(x + 13, y + 0, z + 6, Blocks.grass, 0, 3);
		world.setBlock(x + 14, y + 0, z + 6, Blocks.grass, 0, 3);
		world.setBlock(x + 15, y + 0, z + 6, Blocks.dirt, 0, 3);
		world.setBlock(x + 0, y + 0, z + 7, Blocks.grass, 0, 3);
		world.setBlock(x + 1, y + 0, z + 7, Blocks.dirt, 0, 3);
		world.setBlock(x + 2, y + 0, z + 7, Blocks.grass, 0, 3);
		world.setBlock(x + 3, y + 0, z + 7, Blocks.grass, 0, 3);
		world.setBlock(x + 4, y + 0, z + 7, Blocks.dirt, 0, 3);
		world.setBlock(x + 5, y + 0, z + 7, Blocks.grass, 0, 3);
		world.setBlock(x + 6, y + 0, z + 7, Blocks.grass, 0, 3);
		world.setBlock(x + 7, y + 0, z + 7, Blocks.grass, 0, 3);
		world.setBlock(x + 8, y + 0, z + 7, Blocks.grass, 0, 3);
		world.setBlock(x + 9, y + 0, z + 7, Blocks.grass, 0, 3);
		world.setBlock(x + 10, y + 0, z + 7, Blocks.dirt, 0, 3);
		world.setBlock(x + 11, y + 0, z + 7, Blocks.dirt, 0, 3);
		world.setBlock(x + 12, y + 0, z + 7, Blocks.dirt, 0, 3);
		world.setBlock(x + 13, y + 0, z + 7, Blocks.dirt, 0, 3);
		world.setBlock(x + 14, y + 0, z + 7, Blocks.dirt, 0, 3);
		world.setBlock(x + 15, y + 0, z + 7, Blocks.dirt, 0, 3);
		world.setBlock(x + 0, y + 0, z + 8, Blocks.grass, 0, 3);
		world.setBlock(x + 1, y + 0, z + 8, Blocks.dirt, 0, 3);
		world.setBlock(x + 2, y + 0, z + 8, Blocks.grass, 0, 3);
		world.setBlock(x + 3, y + 0, z + 8, Blocks.grass, 0, 3);
		world.setBlock(x + 4, y + 0, z + 8, Blocks.grass, 0, 3);
		world.setBlock(x + 5, y + 0, z + 8, Blocks.grass, 0, 3);
		world.setBlock(x + 6, y + 0, z + 8, Blocks.grass, 0, 3);
		world.setBlock(x + 7, y + 0, z + 8, Blocks.grass, 0, 3);
		world.setBlock(x + 8, y + 0, z + 8, Blocks.grass, 0, 3);
		world.setBlock(x + 9, y + 0, z + 8, Blocks.grass, 0, 3);
		world.setBlock(x + 10, y + 0, z + 8, Blocks.dirt, 0, 3);
		world.setBlock(x + 11, y + 0, z + 8, Blocks.grass, 0, 3);
		world.setBlock(x + 12, y + 0, z + 8, Blocks.grass, 0, 3);
		world.setBlock(x + 13, y + 0, z + 8, Blocks.grass, 0, 3);
		world.setBlock(x + 14, y + 0, z + 8, Blocks.grass, 0, 3);
		world.setBlock(x + 15, y + 0, z + 8, Blocks.grass, 0, 3);
		world.setBlock(x + 0, y + 0, z + 9, Blocks.grass, 0, 3);
		world.setBlock(x + 1, y + 0, z + 9, Blocks.dirt, 0, 3);
		world.setBlock(x + 2, y + 0, z + 9, Blocks.grass, 0, 3);
		world.setBlock(x + 3, y + 0, z + 9, Blocks.grass, 0, 3);
		world.setBlock(x + 4, y + 0, z + 9, Blocks.grass, 0, 3);
		world.setBlock(x + 5, y + 0, z + 9, Blocks.grass, 0, 3);
		world.setBlock(x + 6, y + 0, z + 9, Blocks.grass, 0, 3);
		world.setBlock(x + 7, y + 0, z + 9, Blocks.grass, 0, 3);
		world.setBlock(x + 8, y + 0, z + 9, Blocks.grass, 0, 3);
		world.setBlock(x + 9, y + 0, z + 9, Blocks.grass, 0, 3);
		world.setBlock(x + 10, y + 0, z + 9, Blocks.dirt, 0, 3);
		world.setBlock(x + 11, y + 0, z + 9, Blocks.grass, 0, 3);
		world.setBlock(x + 12, y + 0, z + 9, Blocks.grass, 0, 3);
		world.setBlock(x + 13, y + 0, z + 9, Blocks.grass, 0, 3);
		world.setBlock(x + 14, y + 0, z + 9, Blocks.grass, 0, 3);
		world.setBlock(x + 15, y + 0, z + 9, Blocks.grass, 0, 3);
		world.setBlock(x + 0, y + 0, z + 10, Blocks.grass, 0, 3);
		world.setBlock(x + 1, y + 0, z + 10, Blocks.dirt, 0, 3);
		world.setBlock(x + 2, y + 0, z + 10, Blocks.grass, 0, 3);
		world.setBlock(x + 3, y + 0, z + 10, Blocks.grass, 0, 3);
		world.setBlock(x + 4, y + 0, z + 10, Blocks.grass, 0, 3);
		world.setBlock(x + 5, y + 0, z + 10, Blocks.grass, 0, 3);
		world.setBlock(x + 6, y + 0, z + 10, Blocks.grass, 0, 3);
		world.setBlock(x + 7, y + 0, z + 10, Blocks.grass, 0, 3);
		world.setBlock(x + 8, y + 0, z + 10, Blocks.grass, 0, 3);
		world.setBlock(x + 9, y + 0, z + 10, Blocks.grass, 0, 3);
		world.setBlock(x + 10, y + 0, z + 10, Blocks.dirt, 0, 3);
		world.setBlock(x + 11, y + 0, z + 10, Blocks.grass, 0, 3);
		world.setBlock(x + 12, y + 0, z + 10, Blocks.grass, 0, 3);
		world.setBlock(x + 13, y + 0, z + 10, Blocks.grass, 0, 3);
		world.setBlock(x + 14, y + 0, z + 10, Blocks.grass, 0, 3);
		world.setBlock(x + 15, y + 0, z + 10, Blocks.grass, 0, 3);
		world.setBlock(x + 0, y + 0, z + 11, Blocks.grass, 0, 3);
		world.setBlock(x + 1, y + 0, z + 11, Blocks.dirt, 0, 3);
		world.setBlock(x + 2, y + 0, z + 11, Blocks.grass, 0, 3);
		world.setBlock(x + 3, y + 0, z + 11, Blocks.grass, 0, 3);
		world.setBlock(x + 4, y + 0, z + 11, Blocks.grass, 0, 3);
		world.setBlock(x + 5, y + 0, z + 11, Blocks.grass, 0, 3);
		world.setBlock(x + 6, y + 0, z + 11, Blocks.grass, 0, 3);
		world.setBlock(x + 7, y + 0, z + 11, Blocks.grass, 0, 3);
		world.setBlock(x + 8, y + 0, z + 11, Blocks.grass, 0, 3);
		world.setBlock(x + 9, y + 0, z + 11, Blocks.grass, 0, 3);
		world.setBlock(x + 10, y + 0, z + 11, Blocks.dirt, 0, 3);
		world.setBlock(x + 11, y + 0, z + 11, Blocks.grass, 0, 3);
		world.setBlock(x + 12, y + 0, z + 11, Blocks.grass, 0, 3);
		world.setBlock(x + 13, y + 0, z + 11, Blocks.grass, 0, 3);
		world.setBlock(x + 14, y + 0, z + 11, Blocks.grass, 0, 3);
		world.setBlock(x + 15, y + 0, z + 11, Blocks.grass, 0, 3);
		world.setBlock(x + 0, y + 0, z + 12, Blocks.grass, 0, 3);
		world.setBlock(x + 1, y + 0, z + 12, Blocks.dirt, 0, 3);
		world.setBlock(x + 2, y + 0, z + 12, Blocks.grass, 0, 3);
		world.setBlock(x + 3, y + 0, z + 12, Blocks.grass, 0, 3);
		world.setBlock(x + 4, y + 0, z + 12, Blocks.grass, 0, 3);
		world.setBlock(x + 5, y + 0, z + 12, Blocks.grass, 0, 3);
		world.setBlock(x + 6, y + 0, z + 12, Blocks.grass, 0, 3);
		world.setBlock(x + 7, y + 0, z + 12, Blocks.grass, 0, 3);
		world.setBlock(x + 8, y + 0, z + 12, Blocks.grass, 0, 3);
		world.setBlock(x + 9, y + 0, z + 12, Blocks.grass, 0, 3);
		world.setBlock(x + 10, y + 0, z + 12, Blocks.dirt, 0, 3);
		world.setBlock(x + 11, y + 0, z + 12, Blocks.grass, 0, 3);
		world.setBlock(x + 12, y + 0, z + 12, Blocks.grass, 0, 3);
		world.setBlock(x + 13, y + 0, z + 12, Blocks.grass, 0, 3);
		world.setBlock(x + 14, y + 0, z + 12, Blocks.grass, 0, 3);
		world.setBlock(x + 15, y + 0, z + 12, Blocks.grass, 0, 3);
		world.setBlock(x + 0, y + 0, z + 13, Blocks.grass, 0, 3);
		world.setBlock(x + 1, y + 0, z + 13, Blocks.dirt, 0, 3);
		world.setBlock(x + 2, y + 0, z + 13, Blocks.grass, 0, 3);
		world.setBlock(x + 3, y + 0, z + 13, Blocks.grass, 0, 3);
		world.setBlock(x + 4, y + 0, z + 13, Blocks.grass, 0, 3);
		world.setBlock(x + 5, y + 0, z + 13, Blocks.grass, 0, 3);
		world.setBlock(x + 6, y + 0, z + 13, Blocks.grass, 0, 3);
		world.setBlock(x + 7, y + 0, z + 13, Blocks.grass, 0, 3);
		world.setBlock(x + 8, y + 0, z + 13, Blocks.grass, 0, 3);
		world.setBlock(x + 9, y + 0, z + 13, Blocks.grass, 0, 3);
		world.setBlock(x + 10, y + 0, z + 13, Blocks.dirt, 0, 3);
		world.setBlock(x + 11, y + 0, z + 13, Blocks.grass, 0, 3);
		world.setBlock(x + 12, y + 0, z + 13, Blocks.grass, 0, 3);
		world.setBlock(x + 13, y + 0, z + 13, Blocks.grass, 0, 3);
		world.setBlock(x + 14, y + 0, z + 13, Blocks.grass, 0, 3);
		world.setBlock(x + 15, y + 0, z + 13, Blocks.grass, 0, 3);
		world.setBlock(x + 0, y + 0, z + 14, Blocks.grass, 0, 3);
		world.setBlock(x + 1, y + 0, z + 14, Blocks.dirt, 0, 3);
		world.setBlock(x + 2, y + 0, z + 14, Blocks.grass, 0, 3);
		world.setBlock(x + 3, y + 0, z + 14, Blocks.grass, 0, 3);
		world.setBlock(x + 4, y + 0, z + 14, Blocks.grass, 0, 3);
		world.setBlock(x + 5, y + 0, z + 14, Blocks.grass, 0, 3);
		world.setBlock(x + 6, y + 0, z + 14, Blocks.grass, 0, 3);
		world.setBlock(x + 7, y + 0, z + 14, Blocks.grass, 0, 3);
		world.setBlock(x + 8, y + 0, z + 14, Blocks.grass, 0, 3);
		world.setBlock(x + 9, y + 0, z + 14, Blocks.grass, 0, 3);
		world.setBlock(x + 10, y + 0, z + 14, Blocks.dirt, 0, 3);
		world.setBlock(x + 11, y + 0, z + 14, Blocks.grass, 0, 3);
		world.setBlock(x + 12, y + 0, z + 14, Blocks.grass, 0, 3);
		world.setBlock(x + 13, y + 0, z + 14, Blocks.grass, 0, 3);
		world.setBlock(x + 14, y + 0, z + 14, Blocks.grass, 0, 3);
		world.setBlock(x + 15, y + 0, z + 14, Blocks.grass, 0, 3);
		world.setBlock(x + 0, y + 0, z + 15, Blocks.grass, 0, 3);
		world.setBlock(x + 1, y + 0, z + 15, Blocks.dirt, 0, 3);
		world.setBlock(x + 2, y + 0, z + 15, Blocks.grass, 0, 3);
		world.setBlock(x + 3, y + 0, z + 15, Blocks.grass, 0, 3);
		world.setBlock(x + 4, y + 0, z + 15, Blocks.grass, 0, 3);
		world.setBlock(x + 5, y + 0, z + 15, Blocks.grass, 0, 3);
		world.setBlock(x + 6, y + 0, z + 15, Blocks.grass, 0, 3);
		world.setBlock(x + 7, y + 0, z + 15, Blocks.grass, 0, 3);
		world.setBlock(x + 8, y + 0, z + 15, Blocks.grass, 0, 3);
		world.setBlock(x + 9, y + 0, z + 15, Blocks.grass, 0, 3);
		world.setBlock(x + 10, y + 0, z + 15, Blocks.dirt, 0, 3);
		world.setBlock(x + 11, y + 0, z + 15, Blocks.grass, 0, 3);
		world.setBlock(x + 12, y + 0, z + 15, Blocks.grass, 0, 3);
		world.setBlock(x + 13, y + 0, z + 15, Blocks.grass, 0, 3);
		world.setBlock(x + 14, y + 0, z + 15, Blocks.grass, 0, 3);
		world.setBlock(x + 15, y + 0, z + 15, Blocks.grass, 0, 3);
		world.setBlock(x + 0, y + 0, z + 16, Blocks.grass, 0, 3);
		world.setBlock(x + 1, y + 0, z + 16, Blocks.dirt, 0, 3);
		world.setBlock(x + 2, y + 0, z + 16, Blocks.grass, 0, 3);
		world.setBlock(x + 3, y + 0, z + 16, Blocks.grass, 0, 3);
		world.setBlock(x + 4, y + 0, z + 16, Blocks.grass, 0, 3);
		world.setBlock(x + 5, y + 0, z + 16, Blocks.grass, 0, 3);
		world.setBlock(x + 6, y + 0, z + 16, Blocks.grass, 0, 3);
		world.setBlock(x + 7, y + 0, z + 16, Blocks.grass, 0, 3);
		world.setBlock(x + 8, y + 0, z + 16, Blocks.grass, 0, 3);
		world.setBlock(x + 9, y + 0, z + 16, Blocks.grass, 0, 3);
		world.setBlock(x + 10, y + 0, z + 16, Blocks.dirt, 0, 3);
		world.setBlock(x + 11, y + 0, z + 16, Blocks.grass, 0, 3);
		world.setBlock(x + 12, y + 0, z + 16, Blocks.grass, 0, 3);
		world.setBlock(x + 13, y + 0, z + 16, Blocks.grass, 0, 3);
		world.setBlock(x + 14, y + 0, z + 16, Blocks.grass, 0, 3);
		world.setBlock(x + 15, y + 0, z + 16, Blocks.grass, 0, 3);
		world.setBlock(x + 0, y + 0, z + 17, Blocks.grass, 0, 3);
		world.setBlock(x + 1, y + 0, z + 17, Blocks.dirt, 0, 3);
		world.setBlock(x + 2, y + 0, z + 17, Blocks.dirt, 0, 3);
		world.setBlock(x + 3, y + 0, z + 17, Blocks.dirt, 0, 3);
		world.setBlock(x + 4, y + 0, z + 17, Blocks.dirt, 0, 3);
		world.setBlock(x + 5, y + 0, z + 17, Blocks.dirt, 0, 3);
		world.setBlock(x + 6, y + 0, z + 17, Blocks.dirt, 0, 3);
		world.setBlock(x + 7, y + 0, z + 17, Blocks.dirt, 0, 3);
		world.setBlock(x + 8, y + 0, z + 17, Blocks.dirt, 0, 3);
		world.setBlock(x + 9, y + 0, z + 17, Blocks.dirt, 0, 3);
		world.setBlock(x + 10, y + 0, z + 17, Blocks.dirt, 0, 3);
		world.setBlock(x + 11, y + 0, z + 17, Blocks.grass, 0, 3);
		world.setBlock(x + 12, y + 0, z + 17, Blocks.grass, 0, 3);
		world.setBlock(x + 13, y + 0, z + 17, Blocks.grass, 0, 3);
		world.setBlock(x + 14, y + 0, z + 17, Blocks.grass, 0, 3);
		world.setBlock(x + 15, y + 0, z + 17, Blocks.grass, 0, 3);
		world.setBlock(x + 1, y + 1, z + 1, Blocks.dirt, 0, 3);
		world.setBlock(x + 2, y + 1, z + 1, Blocks.dirt, 0, 3);
		world.setBlock(x + 3, y + 1, z + 1, Blocks.dirt, 0, 3);
		world.setBlock(x + 4, y + 1, z + 1, Blocks.dirt, 0, 3);
		world.setBlock(x + 5, y + 1, z + 1, Blocks.dirt, 0, 3);
		world.setBlock(x + 6, y + 1, z + 1, Blocks.dirt, 0, 3);
		world.setBlock(x + 7, y + 1, z + 1, Blocks.dirt, 0, 3);
		world.setBlock(x + 8, y + 1, z + 1, Blocks.dirt, 0, 3);
		world.setBlock(x + 9, y + 1, z + 1, Blocks.dirt, 0, 3);
		world.setBlock(x + 10, y + 1, z + 1, Blocks.dirt, 0, 3);
		world.setBlock(x + 11, y + 1, z + 1, Blocks.dirt, 0, 3);
		world.setBlock(x + 12, y + 1, z + 1, Blocks.dirt, 0, 3);
		world.setBlock(x + 13, y + 1, z + 1, Blocks.dirt, 0, 3);
		world.setBlock(x + 14, y + 1, z + 1, Blocks.dirt, 0, 3);
		world.setBlock(x + 15, y + 1, z + 1, Blocks.dirt, 0, 3);
		world.setBlock(x + 1, y + 1, z + 2, Blocks.dirt, 0, 3);
		world.setBlock(x + 8, y + 1, z + 2, Blocks.chest, 3, 3);
		world.setBlock(x + 15, y + 1, z + 2, Blocks.dirt, 0, 3);
		world.setBlock(x + 1, y + 1, z + 3, Blocks.dirt, 0, 3);
		world.setBlock(x + 4, y + 1, z + 3, Blocks.cobblestone, 0, 3);
		world.setBlock(x + 15, y + 1, z + 3, Blocks.dirt, 0, 3);
		world.setBlock(x + 1, y + 1, z + 4, Blocks.dirt, 0, 3);
		world.setBlock(x + 15, y + 1, z + 4, Blocks.wooden_door, 2, 3);
		world.setBlock(x + 1, y + 1, z + 5, Blocks.dirt, 0, 3);
		world.setBlock(x + 2, y + 1, z + 5, Blocks.cobblestone, 0, 3);
		world.setBlock(x + 6, y + 1, z + 5, Blocks.cobblestone, 0, 3);
		world.setBlock(x + 15, y + 1, z + 5, Blocks.dirt, 0, 3);
		world.setBlock(x + 1, y + 1, z + 6, Blocks.dirt, 0, 3);
		world.setBlock(x + 15, y + 1, z + 6, Blocks.dirt, 0, 3);
		world.setBlock(x + 1, y + 1, z + 7, Blocks.dirt, 0, 3);
		world.setBlock(x + 4, y + 1, z + 7, Blocks.cobblestone, 0, 3);
		world.setBlock(x + 10, y + 1, z + 7, Blocks.dirt, 0, 3);
		world.setBlock(x + 11, y + 1, z + 7, Blocks.dirt, 0, 3);
		world.setBlock(x + 12, y + 1, z + 7, Blocks.dirt, 0, 3);
		world.setBlock(x + 13, y + 1, z + 7, Blocks.dirt, 0, 3);
		world.setBlock(x + 14, y + 1, z + 7, Blocks.dirt, 0, 3);
		world.setBlock(x + 15, y + 1, z + 7, Blocks.dirt, 0, 3);
		world.setBlock(x + 1, y + 1, z + 8, Blocks.dirt, 0, 3);
		world.setBlock(x + 10, y + 1, z + 8, Blocks.dirt, 0, 3);
		world.setBlock(x + 1, y + 1, z + 9, Blocks.dirt, 0, 3);
		world.setBlock(x + 10, y + 1, z + 9, Blocks.dirt, 0, 3);
		world.setBlock(x + 1, y + 1, z + 10, Blocks.dirt, 0, 3);
		world.setBlock(x + 10, y + 1, z + 10, Blocks.dirt, 0, 3);
		world.setBlock(x + 1, y + 1, z + 11, Blocks.dirt, 0, 3);
		world.setBlock(x + 10, y + 1, z + 11, Blocks.dirt, 0, 3);
		world.setBlock(x + 1, y + 1, z + 12, Blocks.dirt, 0, 3);
		world.setBlock(x + 10, y + 1, z + 12, Blocks.dirt, 0, 3);
		world.setBlock(x + 1, y + 1, z + 13, Blocks.dirt, 0, 3);
		world.setBlock(x + 10, y + 1, z + 13, Blocks.dirt, 0, 3);
		world.setBlock(x + 1, y + 1, z + 14, Blocks.grass, 0, 3);
		world.setBlock(x + 10, y + 1, z + 14, Blocks.grass, 0, 3);
		world.setBlock(x + 1, y + 1, z + 15, Blocks.grass, 0, 3);
		world.setBlock(x + 10, y + 1, z + 15, Blocks.grass, 0, 3);
		world.setBlock(x + 1, y + 1, z + 16, Blocks.grass, 0, 3);
		world.setBlock(x + 10, y + 1, z + 16, Blocks.grass, 0, 3);
		world.setBlock(x + 1, y + 1, z + 17, Blocks.grass, 0, 3);
		world.setBlock(x + 2, y + 1, z + 17, Blocks.grass, 0, 3);
		world.setBlock(x + 3, y + 1, z + 17, Blocks.grass, 0, 3);
		world.setBlock(x + 4, y + 1, z + 17, Blocks.grass, 0, 3);
		world.setBlock(x + 5, y + 1, z + 17, Blocks.grass, 0, 3);
		world.setBlock(x + 6, y + 1, z + 17, Blocks.grass, 0, 3);
		world.setBlock(x + 7, y + 1, z + 17, Blocks.grass, 0, 3);
		world.setBlock(x + 8, y + 1, z + 17, Blocks.grass, 0, 3);
		world.setBlock(x + 9, y + 1, z + 17, Blocks.grass, 0, 3);
		world.setBlock(x + 10, y + 1, z + 17, Blocks.grass, 0, 3);
		world.setBlock(x + 1, y + 2, z + 1, Blocks.sand, 0, 3);
		world.setBlock(x + 2, y + 2, z + 1, Blocks.sand, 0, 3);
		world.setBlock(x + 3, y + 2, z + 1, Blocks.sand, 0, 3);
		world.setBlock(x + 4, y + 2, z + 1, Blocks.sand, 0, 3);
		world.setBlock(x + 5, y + 2, z + 1, Blocks.sand, 0, 3);
		world.setBlock(x + 6, y + 2, z + 1, Blocks.sand, 0, 3);
		world.setBlock(x + 7, y + 2, z + 1, Blocks.sand, 0, 3);
		world.setBlock(x + 8, y + 2, z + 1, Blocks.sand, 0, 3);
		world.setBlock(x + 9, y + 2, z + 1, Blocks.sand, 0, 3);
		world.setBlock(x + 10, y + 2, z + 1, Blocks.sand, 0, 3);
		world.setBlock(x + 11, y + 2, z + 1, Blocks.sand, 0, 3);
		world.setBlock(x + 12, y + 2, z + 1, Blocks.sand, 0, 3);
		world.setBlock(x + 13, y + 2, z + 1, Blocks.sand, 0, 3);
		world.setBlock(x + 14, y + 2, z + 1, Blocks.sand, 0, 3);
		world.setBlock(x + 15, y + 2, z + 1, Blocks.sand, 0, 3);
		world.setBlock(x + 1, y + 2, z + 2, Blocks.sand, 0, 3);
		world.setBlock(x + 15, y + 2, z + 2, Blocks.sand, 0, 3);
		world.setBlock(x + 1, y + 2, z + 3, Blocks.sand, 0, 3);
		world.setBlock(x + 15, y + 2, z + 3, Blocks.sand, 0, 3);
		world.setBlock(x + 1, y + 2, z + 4, Blocks.sand, 0, 3);
		world.setBlock(x + 15, y + 2, z + 4, Blocks.wooden_door, 8, 3);
		world.setBlock(x + 1, y + 2, z + 5, Blocks.sand, 0, 3);
		world.setBlock(x + 15, y + 2, z + 5, Blocks.sand, 0, 3);
		world.setBlock(x + 1, y + 2, z + 6, Blocks.sand, 0, 3);
		world.setBlock(x + 15, y + 2, z + 6, Blocks.sand, 0, 3);
		world.setBlock(x + 1, y + 2, z + 7, Blocks.sand, 0, 3);
		world.setBlock(x + 10, y + 2, z + 7, Blocks.sand, 0, 3);
		world.setBlock(x + 11, y + 2, z + 7, Blocks.sand, 0, 3);
		world.setBlock(x + 12, y + 2, z + 7, Blocks.sand, 0, 3);
		world.setBlock(x + 13, y + 2, z + 7, Blocks.sand, 0, 3);
		world.setBlock(x + 14, y + 2, z + 7, Blocks.sand, 0, 3);
		world.setBlock(x + 15, y + 2, z + 7, Blocks.sand, 0, 3);
		world.setBlock(x + 1, y + 2, z + 8, Blocks.sand, 0, 3);
		world.setBlock(x + 10, y + 2, z + 8, Blocks.sand, 0, 3);
		world.setBlock(x + 1, y + 2, z + 9, Blocks.sand, 0, 3);
		world.setBlock(x + 10, y + 2, z + 9, Blocks.sand, 0, 3);
		world.setBlock(x + 1, y + 2, z + 10, Blocks.sand, 0, 3);
		world.setBlock(x + 10, y + 2, z + 10, Blocks.sand, 0, 3);
		world.setBlock(x + 1, y + 2, z + 11, Blocks.sand, 0, 3);
		world.setBlock(x + 10, y + 2, z + 11, Blocks.sand, 0, 3);
		world.setBlock(x + 1, y + 2, z + 12, Blocks.sand, 0, 3);
		world.setBlock(x + 10, y + 2, z + 12, Blocks.sand, 0, 3);
		world.setBlock(x + 1, y + 2, z + 13, Blocks.sand, 0, 3);
		world.setBlock(x + 10, y + 2, z + 13, Blocks.sand, 0, 3);
		world.setBlock(x + 1, y + 3, z + 1, Blocks.sand, 0, 3);
		world.setBlock(x + 2, y + 3, z + 1, Blocks.sand, 0, 3);
		world.setBlock(x + 3, y + 3, z + 1, Blocks.sand, 0, 3);
		world.setBlock(x + 4, y + 3, z + 1, Blocks.sand, 0, 3);
		world.setBlock(x + 5, y + 3, z + 1, Blocks.sand, 0, 3);
		world.setBlock(x + 6, y + 3, z + 1, Blocks.sand, 0, 3);
		world.setBlock(x + 7, y + 3, z + 1, Blocks.sand, 0, 3);
		world.setBlock(x + 8, y + 3, z + 1, Blocks.sand, 0, 3);
		world.setBlock(x + 9, y + 3, z + 1, Blocks.sand, 0, 3);
		world.setBlock(x + 10, y + 3, z + 1, Blocks.sand, 0, 3);
		world.setBlock(x + 11, y + 3, z + 1, Blocks.sand, 0, 3);
		world.setBlock(x + 12, y + 3, z + 1, Blocks.sand, 0, 3);
		world.setBlock(x + 13, y + 3, z + 1, Blocks.sand, 0, 3);
		world.setBlock(x + 14, y + 3, z + 1, Blocks.sand, 0, 3);
		world.setBlock(x + 15, y + 3, z + 1, Blocks.sand, 0, 3);
		world.setBlock(x + 1, y + 3, z + 2, Blocks.sand, 0, 3);
		world.setBlock(x + 15, y + 3, z + 2, Blocks.sand, 0, 3);
		world.setBlock(x + 1, y + 3, z + 3, Blocks.sand, 0, 3);
		world.setBlock(x + 15, y + 3, z + 3, Blocks.sand, 0, 3);
		world.setBlock(x + 1, y + 3, z + 4, Blocks.sand, 0, 3);
		world.setBlock(x + 15, y + 3, z + 4, Blocks.sand, 0, 3);
		world.setBlock(x + 1, y + 3, z + 5, Blocks.sand, 0, 3);
		world.setBlock(x + 15, y + 3, z + 5, Blocks.sand, 0, 3);
		world.setBlock(x + 1, y + 3, z + 6, Blocks.sand, 0, 3);
		world.setBlock(x + 15, y + 3, z + 6, Blocks.sand, 0, 3);
		world.setBlock(x + 1, y + 3, z + 7, Blocks.sand, 0, 3);
		world.setBlock(x + 10, y + 3, z + 7, Blocks.sand, 0, 3);
		world.setBlock(x + 11, y + 3, z + 7, Blocks.sand, 0, 3);
		world.setBlock(x + 12, y + 3, z + 7, Blocks.sand, 0, 3);
		world.setBlock(x + 13, y + 3, z + 7, Blocks.sand, 0, 3);
		world.setBlock(x + 14, y + 3, z + 7, Blocks.sand, 0, 3);
		world.setBlock(x + 15, y + 3, z + 7, Blocks.sand, 0, 3);
		world.setBlock(x + 1, y + 3, z + 8, Blocks.sand, 0, 3);
		world.setBlock(x + 10, y + 3, z + 8, Blocks.sand, 0, 3);
		world.setBlock(x + 1, y + 3, z + 9, Blocks.sand, 0, 3);
		world.setBlock(x + 10, y + 3, z + 9, Blocks.sand, 0, 3);
		world.setBlock(x + 1, y + 3, z + 10, Blocks.sand, 0, 3);
		world.setBlock(x + 10, y + 3, z + 10, Blocks.sand, 0, 3);
		world.setBlock(x + 1, y + 3, z + 11, Blocks.sand, 0, 3);
		world.setBlock(x + 10, y + 3, z + 11, Blocks.sand, 0, 3);
		world.setBlock(x + 1, y + 3, z + 12, Blocks.sand, 0, 3);
		world.setBlock(x + 10, y + 3, z + 12, Blocks.sand, 0, 3);
		world.setBlock(x + 1, y + 3, z + 13, Blocks.sand, 0, 3);
		world.setBlock(x + 10, y + 3, z + 13, Blocks.sand, 0, 3);
		world.setBlock(x + 2, y + 3, z + 14, Blocks.crafting_table, 0, 3);
		world.setBlock(x + 3, y + 3, z + 14, Blocks.crafting_table, 0, 3);
		world.setBlock(x + 4, y + 3, z + 14, Blocks.crafting_table, 0, 3);
		world.setBlock(x + 5, y + 3, z + 14, Blocks.crafting_table, 0, 3);
		world.setBlock(x + 6, y + 3, z + 14, Blocks.crafting_table, 0, 3);
		world.setBlock(x + 7, y + 3, z + 14, Blocks.crafting_table, 0, 3);
		world.setBlock(x + 8, y + 3, z + 14, Blocks.crafting_table, 0, 3);
		world.setBlock(x + 9, y + 3, z + 14, Blocks.crafting_table, 0, 3);
		world.setBlock(x + 2, y + 3, z + 15, Blocks.crafting_table, 0, 3);
		world.setBlock(x + 3, y + 3, z + 15, Blocks.crafting_table, 0, 3);
		world.setBlock(x + 4, y + 3, z + 15, Blocks.crafting_table, 0, 3);
		world.setBlock(x + 5, y + 3, z + 15, Blocks.crafting_table, 0, 3);
		world.setBlock(x + 6, y + 3, z + 15, Blocks.crafting_table, 0, 3);
		world.setBlock(x + 7, y + 3, z + 15, Blocks.crafting_table, 0, 3);
		world.setBlock(x + 8, y + 3, z + 15, Blocks.crafting_table, 0, 3);
		world.setBlock(x + 9, y + 3, z + 15, Blocks.crafting_table, 0, 3);
		world.setBlock(x + 2, y + 3, z + 16, Blocks.crafting_table, 0, 3);
		world.setBlock(x + 3, y + 3, z + 16, Blocks.crafting_table, 0, 3);
		world.setBlock(x + 4, y + 3, z + 16, Blocks.crafting_table, 0, 3);
		world.setBlock(x + 5, y + 3, z + 16, Blocks.crafting_table, 0, 3);
		world.setBlock(x + 6, y + 3, z + 16, Blocks.crafting_table, 0, 3);
		world.setBlock(x + 7, y + 3, z + 16, Blocks.crafting_table, 0, 3);
		world.setBlock(x + 8, y + 3, z + 16, Blocks.crafting_table, 0, 3);
		world.setBlock(x + 9, y + 3, z + 16, Blocks.crafting_table, 0, 3);
		world.setBlock(x + 2, y + 4, z + 2, Blocks.crafting_table, 0, 3);
		world.setBlock(x + 3, y + 4, z + 2, Blocks.crafting_table, 0, 3);
		world.setBlock(x + 4, y + 4, z + 2, Blocks.crafting_table, 0, 3);
		world.setBlock(x + 5, y + 4, z + 2, Blocks.crafting_table, 0, 3);
		world.setBlock(x + 6, y + 4, z + 2, Blocks.crafting_table, 0, 3);
		world.setBlock(x + 7, y + 4, z + 2, Blocks.crafting_table, 0, 3);
		world.setBlock(x + 8, y + 4, z + 2, Blocks.crafting_table, 0, 3);
		world.setBlock(x + 9, y + 4, z + 2, Blocks.crafting_table, 0, 3);
		world.setBlock(x + 10, y + 4, z + 2, Blocks.crafting_table, 0, 3);
		world.setBlock(x + 11, y + 4, z + 2, Blocks.crafting_table, 0, 3);
		world.setBlock(x + 12, y + 4, z + 2, Blocks.crafting_table, 0, 3);
		world.setBlock(x + 13, y + 4, z + 2, Blocks.crafting_table, 0, 3);
		world.setBlock(x + 14, y + 4, z + 2, Blocks.crafting_table, 0, 3);
		world.setBlock(x + 2, y + 4, z + 3, Blocks.crafting_table, 0, 3);
		world.setBlock(x + 3, y + 4, z + 3, Blocks.crafting_table, 0, 3);
		world.setBlock(x + 4, y + 4, z + 3, Blocks.crafting_table, 0, 3);
		world.setBlock(x + 5, y + 4, z + 3, Blocks.crafting_table, 0, 3);
		world.setBlock(x + 6, y + 4, z + 3, Blocks.crafting_table, 0, 3);
		world.setBlock(x + 7, y + 4, z + 3, Blocks.crafting_table, 0, 3);
		world.setBlock(x + 8, y + 4, z + 3, Blocks.crafting_table, 0, 3);
		world.setBlock(x + 9, y + 4, z + 3, Blocks.crafting_table, 0, 3);
		world.setBlock(x + 10, y + 4, z + 3, Blocks.crafting_table, 0, 3);
		world.setBlock(x + 11, y + 4, z + 3, Blocks.crafting_table, 0, 3);
		world.setBlock(x + 12, y + 4, z + 3, Blocks.crafting_table, 0, 3);
		world.setBlock(x + 13, y + 4, z + 3, Blocks.crafting_table, 0, 3);
		world.setBlock(x + 14, y + 4, z + 3, Blocks.crafting_table, 0, 3);
		world.setBlock(x + 2, y + 4, z + 4, Blocks.crafting_table, 0, 3);
		world.setBlock(x + 3, y + 4, z + 4, Blocks.crafting_table, 0, 3);
		world.setBlock(x + 4, y + 4, z + 4, Blocks.crafting_table, 0, 3);
		world.setBlock(x + 5, y + 4, z + 4, Blocks.crafting_table, 0, 3);
		world.setBlock(x + 6, y + 4, z + 4, Blocks.crafting_table, 0, 3);
		world.setBlock(x + 7, y + 4, z + 4, Blocks.crafting_table, 0, 3);
		world.setBlock(x + 8, y + 4, z + 4, Blocks.crafting_table, 0, 3);
		world.setBlock(x + 9, y + 4, z + 4, Blocks.crafting_table, 0, 3);
		world.setBlock(x + 10, y + 4, z + 4, Blocks.crafting_table, 0, 3);
		world.setBlock(x + 11, y + 4, z + 4, Blocks.crafting_table, 0, 3);
		world.setBlock(x + 12, y + 4, z + 4, Blocks.crafting_table, 0, 3);
		world.setBlock(x + 13, y + 4, z + 4, Blocks.crafting_table, 0, 3);
		world.setBlock(x + 14, y + 4, z + 4, Blocks.crafting_table, 0, 3);
		world.setBlock(x + 2, y + 4, z + 5, Blocks.crafting_table, 0, 3);
		world.setBlock(x + 3, y + 4, z + 5, Blocks.crafting_table, 0, 3);
		world.setBlock(x + 4, y + 4, z + 5, Blocks.crafting_table, 0, 3);
		world.setBlock(x + 5, y + 4, z + 5, Blocks.crafting_table, 0, 3);
		world.setBlock(x + 6, y + 4, z + 5, Blocks.crafting_table, 0, 3);
		world.setBlock(x + 7, y + 4, z + 5, Blocks.crafting_table, 0, 3);
		world.setBlock(x + 8, y + 4, z + 5, Blocks.crafting_table, 0, 3);
		world.setBlock(x + 9, y + 4, z + 5, Blocks.crafting_table, 0, 3);
		world.setBlock(x + 10, y + 4, z + 5, Blocks.crafting_table, 0, 3);
		world.setBlock(x + 11, y + 4, z + 5, Blocks.crafting_table, 0, 3);
		world.setBlock(x + 12, y + 4, z + 5, Blocks.crafting_table, 0, 3);
		world.setBlock(x + 13, y + 4, z + 5, Blocks.crafting_table, 0, 3);
		world.setBlock(x + 14, y + 4, z + 5, Blocks.crafting_table, 0, 3);
		world.setBlock(x + 2, y + 4, z + 6, Blocks.crafting_table, 0, 3);
		world.setBlock(x + 3, y + 4, z + 6, Blocks.crafting_table, 0, 3);
		world.setBlock(x + 4, y + 4, z + 6, Blocks.crafting_table, 0, 3);
		world.setBlock(x + 5, y + 4, z + 6, Blocks.crafting_table, 0, 3);
		world.setBlock(x + 6, y + 4, z + 6, Blocks.crafting_table, 0, 3);
		world.setBlock(x + 7, y + 4, z + 6, Blocks.crafting_table, 0, 3);
		world.setBlock(x + 8, y + 4, z + 6, Blocks.crafting_table, 0, 3);
		world.setBlock(x + 9, y + 4, z + 6, Blocks.crafting_table, 0, 3);
		world.setBlock(x + 10, y + 4, z + 6, Blocks.crafting_table, 0, 3);
		world.setBlock(x + 11, y + 4, z + 6, Blocks.crafting_table, 0, 3);
		world.setBlock(x + 12, y + 4, z + 6, Blocks.crafting_table, 0, 3);
		world.setBlock(x + 13, y + 4, z + 6, Blocks.crafting_table, 0, 3);
		world.setBlock(x + 14, y + 4, z + 6, Blocks.crafting_table, 0, 3);
		world.setBlock(x + 2, y + 4, z + 7, Blocks.crafting_table, 0, 3);
		world.setBlock(x + 3, y + 4, z + 7, Blocks.crafting_table, 0, 3);
		world.setBlock(x + 4, y + 4, z + 7, Blocks.crafting_table, 0, 3);
		world.setBlock(x + 5, y + 4, z + 7, Blocks.crafting_table, 0, 3);
		world.setBlock(x + 6, y + 4, z + 7, Blocks.crafting_table, 0, 3);
		world.setBlock(x + 7, y + 4, z + 7, Blocks.crafting_table, 0, 3);
		world.setBlock(x + 8, y + 4, z + 7, Blocks.crafting_table, 0, 3);
		world.setBlock(x + 9, y + 4, z + 7, Blocks.crafting_table, 0, 3);
		world.setBlock(x + 2, y + 4, z + 8, Blocks.crafting_table, 0, 3);
		world.setBlock(x + 3, y + 4, z + 8, Blocks.crafting_table, 0, 3);
		world.setBlock(x + 4, y + 4, z + 8, Blocks.crafting_table, 0, 3);
		world.setBlock(x + 5, y + 4, z + 8, Blocks.crafting_table, 0, 3);
		world.setBlock(x + 6, y + 4, z + 8, Blocks.crafting_table, 0, 3);
		world.setBlock(x + 7, y + 4, z + 8, Blocks.crafting_table, 0, 3);
		world.setBlock(x + 8, y + 4, z + 8, Blocks.crafting_table, 0, 3);
		world.setBlock(x + 9, y + 4, z + 8, Blocks.crafting_table, 0, 3);
		world.setBlock(x + 2, y + 4, z + 9, Blocks.crafting_table, 0, 3);
		world.setBlock(x + 3, y + 4, z + 9, Blocks.crafting_table, 0, 3);
		world.setBlock(x + 4, y + 4, z + 9, Blocks.crafting_table, 0, 3);
		world.setBlock(x + 5, y + 4, z + 9, Blocks.crafting_table, 0, 3);
		world.setBlock(x + 6, y + 4, z + 9, Blocks.crafting_table, 0, 3);
		world.setBlock(x + 7, y + 4, z + 9, Blocks.crafting_table, 0, 3);
		world.setBlock(x + 8, y + 4, z + 9, Blocks.crafting_table, 0, 3);
		world.setBlock(x + 9, y + 4, z + 9, Blocks.crafting_table, 0, 3);
		world.setBlock(x + 2, y + 4, z + 10, Blocks.crafting_table, 0, 3);
		world.setBlock(x + 3, y + 4, z + 10, Blocks.crafting_table, 0, 3);
		world.setBlock(x + 4, y + 4, z + 10, Blocks.crafting_table, 0, 3);
		world.setBlock(x + 5, y + 4, z + 10, Blocks.crafting_table, 0, 3);
		world.setBlock(x + 6, y + 4, z + 10, Blocks.crafting_table, 0, 3);
		world.setBlock(x + 7, y + 4, z + 10, Blocks.crafting_table, 0, 3);
		world.setBlock(x + 8, y + 4, z + 10, Blocks.crafting_table, 0, 3);
		world.setBlock(x + 9, y + 4, z + 10, Blocks.crafting_table, 0, 3);
		world.setBlock(x + 2, y + 4, z + 11, Blocks.crafting_table, 0, 3);
		world.setBlock(x + 3, y + 4, z + 11, Blocks.crafting_table, 0, 3);
		world.setBlock(x + 4, y + 4, z + 11, Blocks.crafting_table, 0, 3);
		world.setBlock(x + 5, y + 4, z + 11, Blocks.crafting_table, 0, 3);
		world.setBlock(x + 6, y + 4, z + 11, Blocks.crafting_table, 0, 3);
		world.setBlock(x + 7, y + 4, z + 11, Blocks.crafting_table, 0, 3);
		world.setBlock(x + 8, y + 4, z + 11, Blocks.crafting_table, 0, 3);
		world.setBlock(x + 9, y + 4, z + 11, Blocks.crafting_table, 0, 3);
		world.setBlock(x + 2, y + 4, z + 12, Blocks.crafting_table, 0, 3);
		world.setBlock(x + 3, y + 4, z + 12, Blocks.crafting_table, 0, 3);
		world.setBlock(x + 4, y + 4, z + 12, Blocks.crafting_table, 0, 3);
		world.setBlock(x + 5, y + 4, z + 12, Blocks.crafting_table, 0, 3);
		world.setBlock(x + 6, y + 4, z + 12, Blocks.crafting_table, 0, 3);
		world.setBlock(x + 7, y + 4, z + 12, Blocks.crafting_table, 0, 3);
		world.setBlock(x + 8, y + 4, z + 12, Blocks.crafting_table, 0, 3);
		world.setBlock(x + 9, y + 4, z + 12, Blocks.crafting_table, 0, 3);
		world.setBlock(x + 2, y + 4, z + 13, Blocks.crafting_table, 0, 3);
		world.setBlock(x + 3, y + 4, z + 13, Blocks.crafting_table, 0, 3);
		world.setBlock(x + 4, y + 4, z + 13, Blocks.crafting_table, 0, 3);
		world.setBlock(x + 5, y + 4, z + 13, Blocks.crafting_table, 0, 3);
		world.setBlock(x + 6, y + 4, z + 13, Blocks.crafting_table, 0, 3);
		world.setBlock(x + 7, y + 4, z + 13, Blocks.crafting_table, 0, 3);
		world.setBlock(x + 8, y + 4, z + 13, Blocks.crafting_table, 0, 3);
		world.setBlock(x + 9, y + 4, z + 13, Blocks.crafting_table, 0, 3);
		world.setBlock(x + 2, y + 3, z + 2, Blocks.torch, 3, 3);
		world.setBlock(x + 14, y + 3, z + 6, Blocks.torch, 2, 3);
		world.setBlock(x + 2, y + 3, z + 8, Blocks.torch, 1, 3);
		world.setBlock(x + 9, y + 3, z + 12, Blocks.torch, 2, 3);
		return true;


	}
}